<?xml version="1.0" encoding="UTF-8"?>
<testsuites>
	<testsuite errors="0" failures="2" file="test_calculator.py" name="test_calculator.Testing-20221018113506" skipped="0" tests="4" time="0.003" timestamp="2022-10-18T11:35:06">
		<testcase classname="test_calculator.Testing" file="tests/test_calculator.py" line="9" name="test_add1" time="0.002" timestamp="2022-10-18T11:35:06"/>
		<testcase classname="test_calculator.Testing" file="tests/test_calculator.py" line="12" name="test_multiply1" time="0.000" timestamp="2022-10-18T11:35:06"/>
		<testcase classname="test_calculator.Testing" file="tests/test_calculator.py" line="15" name="test_add2" time="0.000" timestamp="2022-10-18T11:35:06">
			<failure message="2 != 3" type="AssertionError">
<![CDATA[Traceback (most recent call last):
  File "/Users/youngmokcho/instabase/test-sample/tests/test_calculator.py", line 16, in test_add2
    self.assertEqual(self.calc.add(1, 1), 3)
AssertionError: 2 != 3
]]>			</failure>
		</testcase>
		<testcase classname="test_calculator.Testing" file="tests/test_calculator.py" line="18" name="test_multiply2" time="0.000" timestamp="2022-10-18T11:35:06">
			<failure message="0 != 10" type="AssertionError">
<![CDATA[Traceback (most recent call last):
  File "/Users/youngmokcho/instabase/test-sample/tests/test_calculator.py", line 19, in test_multiply2
    self.assertEqual(self.calc.multiply(5, 0), 10)
AssertionError: 0 != 10
]]>			</failure>
		</testcase>
	</testsuite>
</testsuites>
