<?xml version="1.0" encoding="utf-8"?><testsuites><testsuite errors="0" failures="2" hostname="XL29TQJLHC.local" name="pytest" skipped="0" tests="4" time="0.023" timestamp="2022-10-31T13:27:25.626375"><testcase classname="tests.test_calculator.Testing" name="test_add1" time="0.000" /><testcase classname="tests.test_calculator.Testing" name="test_add2" time="0.000"><failure message="AssertionError: 2 != 3">self = &lt;test_calculator.Testing testMethod=test_add2&gt;

    def test_add2(self):
&gt;       self.assertEqual(self.calc.add(1, 1), 3)
E       AssertionError: 2 != 3

tests/test_calculator.py:16: AssertionError</failure></testcase><testcase classname="tests.test_calculator.Testing" name="test_multiply1" time="0.000" /><testcase classname="tests.test_calculator.Testing" name="test_multiply2" time="0.000"><failure message="AssertionError: 0 != 10">self = &lt;test_calculator.Testing testMethod=test_multiply2&gt;

    def test_multiply2(self):
&gt;       self.assertEqual(self.calc.multiply(5, 0), 10)
E       AssertionError: 0 != 10

tests/test_calculator.py:19: AssertionError</failure></testcase></testsuite></testsuites>